Workbook
Name Slicer_Brand: #N/A
Name Slicer_Category: #N/A

Sheet Customer_Dim
A1: Customer_ID | B1: Name | C1: Age | D1: Gender | E1: City | F1: State | G1: Country | H1: Loyalty_Level
A2: CUST1000 | B2: sheena bonilla | C2: 55 | D2: Male | E2: Donaldton | F2: North Carolina | G2: USA
A3: CUST1001 | B3: Eugene Nelson | C3: 26 | D3: Female | E3: Phillipsmouth | F3: North Dakota | G3: USA | H3: Platinum
A4: CUST1002 | B4: dr. Benjamin Price | C4: 29 | D4: Female | E4: Kylebury | F4: Alabama | G4: USA | H4: Platinum
A5: CUST1003 | B5: jeremy harris | C5: 59 | D5: Female | E5: Thomastown | F5: Ohio | G5: USA | H5: Bronze
A6: CUST1004 | B6: Caroline Collins | C6: 64 | D6: Female | E6: Nicholasshire | F6: California | G6: USA | H6: Silver
A7: CUST1005 | B7: Christine Vaughn | C7: 24 | D7: Male | E7: East Amandamouth | F7: Oregon | G7: USA | H7: Bronze
A8: CUST1006 | B8: Amber Jackson | C8: 29 | D8: Female | E8: Deborahborough | F8: South Dakota | G8: USA | H8: Platinum
A9: CUST1007 | B9: Daniel Boyd | C9: 29 | D9: Female | E9: West Pamelafurt | F9: West Virginia | G9: USA | H9: Bronze
A10: CUST1008 | B10: Melissa Howard | C10: 53 | D10: Female | E10: Maynardton | F10: New Hampshire | G10: USA | H10: Gold
A11: CUST1009 | B11: Ms. Maria Leach | C11: 64 | D11: Male | E11: Melissashire | F11: Pennsylvania | G11: USA | H11: Platinum
A12: CUST1010 | B12: Dominic Page | C12: 53 | D12: Male | E12: Port Michaelburgh | F12: Pennsylvania | G12: USA | H12: Bronze
A13: CUST1011 | B13: Brian Lopez | C13: 28 | D13: Female | E13: East Krista | F13: New York | G13: USA | H13: Gold
A14: CUST1012 | B14: Kenneth Lambert | C14: 55 | D14: Female | E14: North Kathryn | F14: Kansas | G14: USA | H14: Platinum
... A19: CUST1017 | B19: Adam Cruz | C19: 60 | D19: Female | E19: Brandonville | F19: Georgia | G19: USA | H19: Platinum
A20: CUST1018 | B20: Rhonda Moss | C20: 43 | D20: Male | E20: South William | F20: Kansas | G20: USA
A21: CUST1019 | B21: Michael Torres | C21: 46 | D21: Female | E21: Gonzalezfort | F21: New Jersey | G21: USA | H21: Platinum
A22: CUST1020 | B22: Bridget Allen | C22: 59 | D22: Male | E22: Lake Shaneburgh | F22: Delaware | G22: USA | H22: Silver
A23: CUST1021 | B23: Jeff Martinez | C23: 36 | D23: Female | E23: Smithburgh | F23: Oklahoma | G23: USA | H23: Gold
A24: CUST1022 | B24: paul fox | C24: 33 | D24: Female | E24: Michaelton | F24: Hawaii | G24: USA | H24: Silver
A25: CUST1023 | B25: Jonathan Steele | C25: 52 | D25: Female | E25: Molinabury | F25: Oregon | G25: USA | H25: Silver
A26: CUST1024 | B26: Heather Collins | C26: 40 | D26: Male | E26: Rogerschester | F26: Idaho | G26: USA | H26: Platinum
A27: CUST1025 | B27: Diana Taylor | C27: 59 | D27: Female | E27: Vasqueztown | F27: California | G27: USA | H27: Bronze
A28: CUST1026 | B28: Amber Carlson | C28: 18 | D28: Female | E28: East Michellemouth | F28: Missouri | G28: USA | H28: Gold
A29: CUST1027 | B29: Leslie Johnson | C29: 31 | D29: Male | E29: Mollyshire | F29: Utah | G29: USA
A30: CUST1028 | B30: Joshua Ryan | C30: 27 | D30: Female | E30: New David | F30: New Jersey | G30: USA | H30: Platinum
A31: CUST1029 | B31: David Arnold | C31: 54 | D31: Female | E31: East Jennifer | F31: California | G31: USA | H31: Silver
A32: CUST1030 | B32: Jessica Acevedo | C32: 64 | D32: Female | E32: Amybury | F32: Pennsylvania | G32: USA | H32: Bronze
A33: CUST1031 | B33: Sarah Vance | C33: 41 | D33: Male | E33: Johnsonville | F33: Oregon | G33: USA | H33: Silver
A34: CUST1032 | B34: Mike Jennings | C34: 48 | D34: Female | E34: Fostermouth | F34: Arizona | G34: USA | H34: Gold
A35: CUST1033 | B35: Robert Jones DDS | C35: 25 | D35: Male | E35: Tristanton | F35: Oklahoma | G35: USA | H35: Platinum
A36: CUST1034 | B36: Christopher Olson | C36: 27 | D36: Female | E36: West Richard | F36: Maryland | G36: USA | H36: Platinum
A37: CUST1035 | B37: Rachel Myers | C37: 52 | D37: Male | E37: Robertberg | F37: North Dakota | G37: USA | H37: Silver
A38: CUST1036 | B38: Thomas Phillips | C38: 20 | D38: Female | E38: Luisfurt | F38: Georgia | G38: USA | H38: Gold
A39: CUST1037 | B39: Christopher Carter | C39: 27 | D39: Female | E39: Brendastad | F39: South Dakota | G39: USA
A40: CUST1038 | B40: Deanna Simpson | C40: 35 | D40: Female | E40: Brownport | F40: North Dakota | G40: USA | H40: Bronze
A41: CUST1039 | B41: Tonya Reynolds | C41: 55 | D41: Female | E41: Darleneton | F41: Michigan | G41: USA | H41: Gold
A42: CUST1040 | B42: Eric Vega | C42: 50 | D42: Male | E42: Williamsonland | F42: Kansas | G42: USA | H42: Gold
A43: CUST1041 | B43: James Gibbs | C43: 21 | D43: Male | E43: Mooneyshire | F43: Alaska | G43: USA | H43: Platinum
A44: CUST1042 | B44: William Martin | C44: 19 | D44: Male | E44: Ryanburgh | F44: Connecticut | G44: USA | H44: Platinum
...

Sheet Product_Dim
A1: Product_ID | B1: Product_Name | C1: Category | D1: Sub_Category | E1: Brand | F1: Cost | G1: Stock
A2: PROD0 | B2: Brother Laser Printer | C2: Electronics | D2: Computer | E2: Hunt Inc | F2: 112.42 | G2: 416
A3: PROD1 | B3: Men's Graphic T-Shirt | C3: Clothing | D3: Tops | E3: Terry-Moore | F3: 342.56 | G3: 181
A4: PROD2 | B4: Women's Casual Hoodie | C4: Clothing | D4: Outerwear | E4: Sims Inc | G4: 352
A5: P-3 | B5: Men's Running Jacket | C5: Clothing | D5: Outerwear | E5: Pineda Ltd | F5: 364.67 | G5: 452
A6: PROD4 | B6: Women's Yoga Pants | C6: Clothing | D6: Bottoms | E6: Gonzales-Davis | F6: 306.46 | G6: 487
A7: PROD5 | B7: Men's Leather Belt | C7: Clothing | D7: Accessories | E7: Baldwin, Garza and Gonzalez | F7: 261 | G7: 59
A8: PROD6 | B8: Herbal Face Moisturizer | C8: Beauty | D8: Skincare | E8: Davidson PLC | F8: 312.8 | G8: 350
A9: PROD7 | B9: LED Table Lamp | C9: Home | D9: Lighting | E9: Harrell LLC | F9: 218.86 | G9: 170
A10: PROD8 | B10: Wireless Bluetooth Earbuds | C10: Electronics | D10: Audio | E10: Perez-Johnston | F10: 439.07 | G10: 142
A11: PROD9 | B11: Adjustable Dumbbell Set | C11: Sports | D11: Fitness | E11: Hill PLC | F11: 495.72 | G11: 323
A12: PROD10 | B12: Ceramic Kitchen Bowl Set | C12: Home | D12: Kitchen | E12: Hamilton Group | F12: 298.86 | G12: 308
A13: PROD11 | B13: HD Smart TV Stick | C13: Electronics | D13: Accessories | E13: Gibson, Hobbs and Weaver | F13: 449.4
A14: PROD12 | B14: Hair Strengthening Shampoo | C14: Beauty | D14: Haircare | E14: Rice LLC | F14: 115.82 | G14: 460
A15: PROD13 | B15: USB-C Fast Charger | C15: Electronics | D15: Accessories | E15: Dawson-Perkins | F15: 242.23 | G15: 453
A16: PROD14 | B16: Decorative Wall Mirror | C16: Home | D16: Decor | E16: Luna, Anderson and Bowman | F16: 48.01 | G16: 439
A17: PROD15 | B17: 4K Home Projector | C17: Electronics | D17: Appliances | E17: Thomas LLC | F17: 465.34 | G17: 301
A18: P-16 | B18: Beard Grooming Kit | C18: Beauty | D18: Grooming | E18: Erickson-Green | F18: 337.42 | G18: 256
A19: PROD17 | B19: Soccer Training Cone Set | C19: Sports | D19: Accessories | E19: Ford, Murphy and Wilson | F19: 144.53 | G19: 367
A20: PROD18 | B20: Women's Denim Jeans | C20: Clothing | D20: Bottoms | E20: Guerra-Hendrix | G20: 343
A21: PROD19 | B21: Knee Support Brace | C21: Sports | D21: Equipment | E21: May-Reese | F21: 21.34 | G21: 65
A22: PROD20 | B22: Outdoor Sports Water Bottle | C22: Sports | D22: Accessories | E22: Soto-Ellis | F22: 131.51
A23: PROD21 | B23: Multi-Purpose Storage Box | C23: Home | D23: Storage | E23: Gardner-Montes | F23: 123.46 | G23: 76
A24: PROD22 | B24: Carbon Fiber Tennis Racket | C24: Sports | D24: Equipment | E24: Flores, Pineda and Rodriguez | F24: 484.62 | G24: 432
A25: PROD23 | B25: Men's Formal Shirt | C25: Clothing | D25: Tops | E25: Moon, Mora and Santos | G25: 360
A26: PROD24 | B26: Foldable Camping Chair | C26: Sports | D26: Outdoor | E26: Cook Ltd | F26: 166.06 | G26: 340
A27: PROD25 | B27: Women's Scarf Set | C27: Clothing | D27: Accessories | E27: Brown and Sons | F27: 174.02 | G27: 268
A28: PROD26 | B28: Wireless Bluetooth Speaker | C28: Electronics | D28: Audio | E28: Reed-Schmidt | F28: 322.41 | G28: 213
A29: PROD27 | B29: Decorative Floor Vase | C29: Home | D29: Decor | E29: Khan, Jones and Paul | G29: 378
A30: PROD28 | B30: Sports Stopwatch Timer | C30: Sports | D30: Accessories | E30: Burns-Hansen | F30: 38.76 | G30: 137
A31: PROD29 | B31: Fabric Sofa Throw Blanket | C31: Home | D31: Decor | E31: Hoffman Group | F31: 218.48 | G31: 276
A32: PROD30 | B32: Stainless Steel Cutlery Set | C32: Home | D32: Kitchen | E32: Stevens, Fernandez and Martin | F32: 19.52 | G32: 57
A33: PROD31 | B33: Basketball | C33: Sports | D33: Team Sports | E33: Nolan-Snow | F33: 204.39 | G33: 281
A34: PROD32 | B34: Vitamin C Face Serum | C34: Beauty | D34: Skincare | E34: Griffin Ltd | F34: 283.83 | G34: 244
A35: PROD33 | B35: Modern Wall Clock | C35: Home | D35: Decor | E35: Weiss-Watson | F35: 179.77 | G35: 305
A36: PROD34 | B36: Gaming Mechanical Keyboard | C36: Electronics | D36: Computer | E36: Lucero LLC | F36: 419.28 | G36: 86
A37: PROD35 | B37: Bedroom Table Lamp | C37: Home | D37: Lighting | E37: Jones LLC | F37: 382.22 | G37: 329
A38: PROD36 | B38: Women's Summer Dress | C38: Clothing | D38: Tops | E38: Smith-Mills | F38: 223.43 | G38: 154
A39: PROD37 | B39: Men's Casual Sneakers | C39: Clothing | D39: Footwear | E39: Hogan-Lee | F39: 353.47 | G39: 214
A40: PROD38 | B40: Sports Water Hydration Pack | C40: Sports | D40: Outdoor | E40: Sims-Smith | F40: 135.61 | G40: 394
...

Sheet Store_Dim
A1: Store_ID | B1: Store_Name | C1: Region | D1: City | E1: Store_Type
A2: STORE0 | B2: Rivera-Warner | C2: East | D2: Washingtonfurt | E2: Flagship
A3: STORE1 | B3: Martinez, Adkins and Johnson | C3: North | D3: Danielmouth | E3: Flagship
A4: STORE2 | B4: Black-Horn | C4: South | D4: North Nancyview | E4: Outlet
A5: STORE3 | B5: Johnson-Wright | C5: North | D5: Hoodberg | E5: Outlet
A6: STORE4 | B6: Alexander Group | C6: South | D6: Port Sharon | E6: Online
A7: STORE5 | B7: Gray Ltd | C7: North | D7: New Michaelchester | E7: Outlet
A8: STORE6 | B8: Benson-Elliott | C8: East | D8: Port Josephberg | E8: Online
A9: STORE7 | B9: Martinez-Mullins | C9: South | D9: Williamsfurt | E9: Online
A10: STORE8 | B10: Bean, Jones and Park | C10: West | D10: Thompsonborough | E10: Online
A11: STORE9 | B11: Moore, Padilla and Butler | C11: South | D11: East Johnstad | E11: Flagship
A12: STORE10 | B12: Hill, Wagner and Ballard | C12: East | D12: East Davidville | E12: Online
... A21: STORE19 | B21: Mann-Austin | C21: East | D21: Vasquezborough | E21: Online

Sheet Sales_Fact
A1: Sales_ID | B1: Order_Date | C1: Customer_ID | D1: Product_ID | E1: Store_ID | F1: Quantity | G1: Unit_Price | H1: Discount | I1: Payment_Type | J1: Total_Amount
A2: SALE0 | B2: 45480 | C2: CUST1409 | D2: PROD97 | E2: STORE3 | F2: 1 | G2: 218.04 | H2: 0.09 | I2: Credit Card | J2: 198.4164
A3: SALE1 | B3: 45285 | C3: CUST1467 | D3: PROD74 | E3: STORE17 | F3: 3 | G3: 104.47 | H3: 0.27 | I3: PayPal | J3: 228.7893
A4: SALE2 | B4: 45446 | C4: CUST1056 | D4: PROD49 | E4: STORE8 | F4: 4 | G4: 914.05 | H4: 0.25 | I4: Credit Card | J4: 2742.15
A5: SALE3 | B5: 45259 | C5: CUST1346 | D5: PROD76 | E5: STORE8 | F5: 1 | G5: 921.51 | H5: 0.16 | I5: COD | J5: 774.0684
A6: SALE4 | B6: 45297 | C6: CUST1493 | D6: PROD59 | E6: STORE5 | F6: 3 | G6: 745.3 | H6: 0.18 | I6: Credit Card | J6: 1833.438
A7: SALE5 | B7: 45499 | C7: CUST1116 | D7: PROD15 | E7: STORE7 | F7: 3 | G7: 147.01 | H7: 0.19 | I7: COD | J7: 357.2343
A8: SALE6 | B8: 45850 | C8: CUST1016 | D8: PROD56 | E8: STORE4 | F8: 2 | G8: 785.31 | H8: 0.15 | I8: PayPal | J8: 1335.027
A9: SALE7 | B9: 45248 | C9: CUST1152 | D9: PROD70 | E9: STORE8 | F9: 4 | G9: 342.39 | H9: 0.23 | I9: PayPal | J9: 1054.5612
A10: SALE8 | B10: 45781 | C10: CUST1187 | D10: PROD99 | E10: STORE5 | G10: 448.25 | H10: 0.07 | I10: PayPal | J10: 1250.6175
A11: SALE9 | B11: 45869 | C11: CUST1464 | D11: PROD33 | E11: STORE0 | F11: 2 | G11: 873.17 | H11: 0.23 | I11: PayPal | J11: 1344.6818
A12: SALE10 | B12: 45335 | C12: CUST1065 | D12: PROD24 | E12: STORE14 | F12: 1 | G12: 278.63 | H12: 0.07 | I12: Credit Card | J12: 259.1259
A13: SALE11 | B13: 45801 | C13: CUST1320 | D13: PROD39 | E13: STORE1 | F13: 4 | G13: 286.92 | H13: 0.17 | I13: Credit Card | J13: 952.5744
A14: SALE12 | B14: 45528 | C14: CUST1237 | D14: PROD88 | E14: STORE4 | F14: 4 | G14: 644.58 | H14: 0.01 | I14: Credit Card | J14: 2552.5368
A15: SALE13 | B15: 45875 | C15: CUST1443 | D15: PROD34 | E15: STORE16 | F15: 2 | G15: 316.9 | H15: 0.3 | I15: PayPal | J15: 443.66
A16: SALE14 | B16: 45829 | C16: CUST1348 | D16: PROD24 | E16: STORE15 | F16: 4 | G16: 403.47 | H16: 0.29 | I16: PayPal | J16: 1145.8548
A17: SALE15 | B17: 45636 | C17: CUST1435 | D17: PROD36 | E17: STORE9 | G17: 871.34 | H17: 0.04 | I17: COD | J17: 2509.4592
A18: SALE16 | B18: 45913 | C18: CUST1276 | D18: PROD65 | E18: STORE19 | F18: 2 | G18: 451.98 | H18: 0.25 | I18: Credit Card | J18: 677.97
A19: SALE17 | B19: 45637 | C19: CUST1079 | D19: PROD27 | E19: STORE4 | F19: 2 | G19: 502.69 | H19: 0.23 | I19: Credit Card | J19: 774.1426
A20: SALE18 | B20: 45517 | C20: CUST1094 | D20: PROD39 | E20: STORE4 | F20: 2 | G20: 559.23 | H20: 0.25 | I20: COD | J20: 838.845
A21: SALE19 | B21: 45369 | C21: CUST1239 | D21: PROD60 | E21: STORE13 | F21: 4 | H21: 0.04 | I21: COD | J21: 1782.4512
A22: SALE20 | B22: 45843 | C22: CUST1144 | D22: PROD72 | E22: STORE17 | F22: 3 | G22: 986.04 | H22: 0.27 | I22: COD | J22: 2159.4276
A23: SALE21 | B23: 45447 | C23: CUST1396 | D23: PROD43 | E23: STORE18 | F23: 1 | G23: 589.56 | H23: 0.22 | I23: Credit Card | J23: 459.8568
A24: SALE22 | B24: 45394 | C24: CUST1476 | D24: PROD69 | E24: STORE10 | F24: 3 | G24: 979.42 | H24: 0.03 | I24: PayPal | J24: 2850.1122
A25: SALE23 | B25: 45466 | C25: CUST1368 | D25: PROD12 | E25: STORE8 | F25: 1 | G25: 719.28 | H25: 0.08 | I25: Credit Card | J25: 661.7376
A26: SALE24 | B26: 45908 | C26: CUST1186 | D26: PROD67 | E26: STORE6 | F26: 3 | G26: 77.6 | H26: 0.07 | I26: Credit Card | J26: 216.504
A27: SALE25 | B27: 45552 | C27: CUST1381 | D27: PROD5 | E27: STORE3 | F27: 4 | G27: 852.71 | H27: 0.14 | I27: PayPal | J27: 2933.3224
A28: SALE26 | B28: 45294 | C28: CUST1213 | D28: PROD98 | E28: STORE8 | F28: 4 | G28: 156.16 | I28: Credit Card | J28: 599.6544
A29: SALE27 | B29: 45710 | C29: CUST1200 | D29: PROD77 | E29: STORE8 | F29: 3 | G29: 815.49 | H29: 0.17 | I29: Credit Card | J29: 2030.5701
A30: SALE28 | B30: 45923 | C30: CUST1148 | D30: PROD13 | E30: STORE2 | F30: 2 | G30: 74.21 | H30: 0.11 | I30: PayPal | J30: 132.0938
A31: SALE29 | B31: 45302 | C31: CUST1348 | D31: PROD99 | E31: STORE3 | G31: 451.67 | H31: 0.15 | I31: Credit Card | J31: 1535.678
A32: SALE30 | B32: 45217 | C32: CUST1028 | D32: PROD5 | E32: STORE19 | F32: 1 | G32: 429.38 | H32: 0.13 | I32: PayPal | J32: 373.5606
A33: SALE31 | B33: 45593 | C33: CUST1412 | D33: PROD53 | E33: STORE12 | F33: 2 | G33: 148.96 | H33: 0.03 | I33: COD | J33: 288.9824
A34: SALE32 | B34: 45597 | C34: CUST1398 | D34: PROD75 | E34: STORE8 | F34: 4 | G34: 313.83 | H34: 0.08 | I34: Credit Card | J34: 1154.8944
A35: SALE33 | B35: 45620 | C35: CUST1453 | D35: PROD12 | E35: STORE6 | F35: 2 | G35: 717.31 | H35: 0.15 | I35: Credit Card | J35: 1219.427
A36: SALE34 | B36: 45215 | C36: CUST1344 | D36: PROD79 | E36: STORE1 | G36: 873.22 | H36: 0.18 | I36: Credit Card | J36: 2148.1212
A37: SALE35 | B37: 45878 | C37: CUST1218 | D37: PROD16 | E37: STORE3 | F37: 4 | G37: 109.36 | H37: 0.19 | I37: COD | J37: 354.3264
A38: SALE36 | B38: 45635 | C38: CUST1086 | D38: PROD5 | E38: STORE7 | F38: 3 | G38: 559.52 | H38: 0.16 | I38: PayPal | J38: 1409.9904
A39: SALE37 | B39: 45329 | C39: CUST1492 | D39: PROD10 | E39: STORE17 | F39: 3 | G39: 121.76 | H39: 0.27 | I39: PayPal | J39: 266.6544
A40: SALE38 | B40: 45378 | C40: CUST1189 | D40: PROD33 | E40: STORE13 | F40: 4 | G40: 735.32 | H40: 0.06 | I40: COD | J40: 2764.8032
...

Sheet Customer
A1: Customer_ID | B1: Name | C1: Age | D1: Gender | E1: City | F1: State | G1: Country | H1: Loyalty_Level | I1: Name Corrected | J1: Loyaly Level Corrected
A2: CUST1000 | B2: sheena bonilla | C2: 55 | D2: Male | E2: Donaldton | F2: North Carolina | G2: USA | I2: =TRIM(PROPER(B2)) -> Sheena Bonilla | J2: {=IF(H2<>"", H2, INDEX($H$2:$H$501, MODE(IF($H$2:$H$501<>"", MATCH($H$2:$H$501, $H$2:$H$501, 0)))))} -> Platinum
A3: CUST1001 | B3: Eugene Nelson | C3: 26 | D3: Female | E3: Phillipsmouth | F3: North Dakota | G3: USA | H3: Platinum | I3: =TRIM(PROPER(B3)) -> Eugene Nelson | J3: {=IF(H3<>"", H3, INDEX($H$2:$H$501, MODE(IF($H$2:$H$501<>"", MATCH($H$2:$H$501, $H$2:$H$501, 0)))))} -> Platinum
A4: CUST1002 | B4: dr. Benjamin Price | C4: 29 | D4: Female | E4: Kylebury | F4: Alabama | G4: USA | H4: Platinum | I4: =TRIM(PROPER(B4)) -> Dr. Benjamin Price | J4: {=IF(H4<>"", H4, INDEX($H$2:$H$501, MODE(IF($H$2:$H$501<>"", MATCH($H$2:$H$501, $H$2:$H$501, 0)))))} -> Platinum | L4: Summary
A5: CUST1003 | B5: jeremy harris | C5: 59 | D5: Female | E5: Thomastown | F5: Ohio | G5: USA | H5: Bronze | I5: =TRIM(PROPER(B5)) -> Jeremy Harris | J5: {=IF(H5<>"", H5, INDEX($H$2:$H$501, MODE(IF($H$2:$H$501<>"", MATCH($H$2:$H$501, $H$2:$H$501, 0)))))} -> Bronze | L5: 1)I use trim and proper formula to correct the name
A6: CUST1004 | B6: Caroline Collins | C6: 64 | D6: Female | E6: Nicholasshire | F6: California | G6: USA | H6: Silver | I6: =TRIM(PROPER(B6)) -> Caroline Collins | J6: {=IF(H6<>"", H6, INDEX($H$2:$H$501, MODE(IF($H$2:$H$501<>"", MATCH($H$2:$H$501, $H$2:$H$501, 0)))))} -> Silver | L6: 2)I use if, index, match formula to take mode for loyalty level
A7: CUST1005 | B7: Christine Vaughn | C7: 24 | D7: Male | E7: East Amandamouth | F7: Oregon | G7: USA | H7: Bronze | I7: =TRIM(PROPER(B7)) -> Christine Vaughn | J7: {=IF(H7<>"", H7, INDEX($H$2:$H$501, MODE(IF($H$2:$H$501<>"", MATCH($H$2:$H$501, $H$2:$H$501, 0)))))} -> Bronze | L7: 3) C-1486, C-1491, C-1496,… are corrected by using find and replace
A8: CUST1006 | B8: Amber Jackson | C8: 29 | D8: Female | E8: Deborahborough | F8: South Dakota | G8: USA | H8: Platinum | I8: =TRIM(PROPER(B8)) -> Amber Jackson | J8: {=IF(H8<>"", H8, INDEX($H$2:$H$501, MODE(IF($H$2:$H$501<>"", MATCH($H$2:$H$501, $H$2:$H$501, 0)))))} -> Platinum
A9: CUST1007 | B9: Daniel Boyd | C9: 29 | D9: Female | E9: West Pamelafurt | F9: West Virginia | G9: USA | H9: Bronze | I9: =TRIM(PROPER(B9)) -> Daniel Boyd | J9: {=IF(H9<>"", H9, INDEX($H$2:$H$501, MODE(IF($H$2:$H$501<>"", MATCH($H$2:$H$501, $H$2:$H$501, 0)))))} -> Bronze
A10: CUST1008 | B10: Melissa Howard | C10: 53 | D10: Female | E10: Maynardton | F10: New Hampshire | G10: USA | H10: Gold | I10: =TRIM(PROPER(B10)) -> Melissa Howard | J10: {=IF(H10<>"", H10, INDEX($H$2:$H$501, MODE(IF($H$2:$H$501<>"", MATCH($H$2:$H$501, $H$2:$H$501, 0)))))} -> Gold
A11: CUST1009 | B11: Ms. Maria Leach | C11: 64 | D11: Male | E11: Melissashire | F11: Pennsylvania | G11: USA | H11: Platinum | I11: =TRIM(PROPER(B11)) -> Ms. Maria Leach | J11: {=IF(H11<>"", H11, INDEX($H$2:$H$501, MODE(IF($H$2:$H$501<>"", MATCH($H$2:$H$501, $H$2:$H$501, 0)))))} -> Platinum
A12: CUST1010 | B12: Dominic Page | C12: 53 | D12: Male | E12: Port Michaelburgh | F12: Pennsylvania | G12: USA | H12: Bronze | I12: =TRIM(PROPER(B12)) -> Dominic Page | J12: {=IF(H12<>"", H12, INDEX($H$2:$H$501, MODE(IF($H$2:$H$501<>"", MATCH($H$2:$H$501, $H$2:$H$501, 0)))))} -> Bronze
A13: CUST1011 | B13: Brian Lopez | C13: 28 | D13: Female | E13: East Krista | F13: New York | G13: USA | H13: Gold | I13: =TRIM(PROPER(B13)) -> Brian Lopez | J13: {=IF(H13<>"", H13, INDEX($H$2:$H$501, MODE(IF($H$2:$H$501<>"", MATCH($H$2:$H$501, $H$2:$H$501, 0)))))} -> Gold
A14: CUST1012 | B14: Kenneth Lambert | C14: 55 | D14: Female | E14: North Kathryn | F14: Kansas | G14: USA | H14: Platinum | I14: =TRIM(PROPER(B14)) -> Kenneth Lambert | J14: {=IF(H14<>"", H14, INDEX($H$2:$H$501, MODE(IF($H$2:$H$501<>"", MATCH($H$2:$H$501, $H$2:$H$501, 0)))))} -> Platinum
A15: CUST1013 | B15: Nathan Hernandez | C15: 32 | D15: Female | E15: New Becky | F15: Montana | G15: USA | H15: Silver | I15: =TRIM(PROPER(B15)) -> Nathan Hernandez | J15: {=IF(H15<>"", H15, INDEX($H$2:$H$501, MODE(IF($H$2:$H$501<>"", MATCH($H$2:$H$501, $H$2:$H$501, 0)))))} -> Silver
A16: CUST1014 | B16: Ashley Cohen | C16: 53 | D16: Female | E16: Lake Kristamouth | F16: Nebraska | G16: USA | H16: Silver | I16: =TRIM(PROPER(B16)) -> Ashley Cohen | J16: {=IF(H16<>"", H16, INDEX($H$2:$H$501, MODE(IF($H$2:$H$501<>"", MATCH($H$2:$H$501, $H$2:$H$501, 0)))))} -> Silver
A17: CUST1015 | B17: Laura Alvarez | C17: 49 | D17: Female | E17: Lawsonhaven | F17: Washington | G17: USA | H17: Platinum | I17: =TRIM(PROPER(B17)) -> Laura Alvarez | J17: {=IF(H17<>"", H17, INDEX($H$2:$H$501, MODE(IF($H$2:$H$501<>"", MATCH($H$2:$H$501, $H$2:$H$501, 0)))))} -> Platinum
A18: CUST1016 | B18: John Scott | C18: 24 | D18: Female | E18: South Christopher | F18: Pennsylvania | G18: USA | H18: Bronze | I18: =TRIM(PROPER(B18)) -> John Scott | J18: {=IF(H18<>"", H18, INDEX($H$2:$H$501, MODE(IF($H$2:$H$501<>"", MATCH($H$2:$H$501, $H$2:$H$501, 0)))))} -> Bronze
A19: CUST1017 | B19: Adam Cruz | C19: 60 | D19: Female | E19: Brandonville | F19: Georgia | G19: USA | H19: Platinum | I19: =TRIM(PROPER(B19)) -> Adam Cruz | J19: {=IF(H19<>"", H19, INDEX($H$2:$H$501, MODE(IF($H$2:$H$501<>"", MATCH($H$2:$H$501, $H$2:$H$501, 0)))))} -> Platinum
A20: CUST1018 | B20: Rhonda Moss | C20: 43 | D20: Male | E20: South William | F20: Kansas | G20: USA | I20: =TRIM(PROPER(B20)) -> Rhonda Moss | J20: {=IF(H20<>"", H20, INDEX($H$2:$H$501, MODE(IF($H$2:$H$501<>"", MATCH($H$2:$H$501, $H$2:$H$501, 0)))))} -> Platinum
A21: CUST1019 | B21: Michael Torres | C21: 46 | D21: Female | E21: Gonzalezfort | F21: New Jersey | G21: USA | H21: Platinum | I21: =TRIM(PROPER(B21)) -> Michael Torres | J21: {=IF(H21<>"", H21, INDEX($H$2:$H$501, MODE(IF($H$2:$H$501<>"", MATCH($H$2:$H$501, $H$2:$H$501, 0)))))} -> Platinum
A22: CUST1020 | B22: Bridget Allen | C22: 59 | D22: Male | E22: Lake Shaneburgh | F22: Delaware | G22: USA | H22: Silver | I22: =TRIM(PROPER(B22)) -> Bridget Allen | J22: {=IF(H22<>"", H22, INDEX($H$2:$H$501, MODE(IF($H$2:$H$501<>"", MATCH($H$2:$H$501, $H$2:$H$501, 0)))))} -> Silver
A23: CUST1021 | B23: Jeff Martinez | C23: 36 | D23: Female | E23: Smithburgh | F23: Oklahoma | G23: USA | H23: Gold | I23: =TRIM(PROPER(B23)) -> Jeff Martinez | J23: {=IF(H23<>"", H23, INDEX($H$2:$H$501, MODE(IF($H$2:$H$501<>"", MATCH($H$2:$H$501, $H$2:$H$501, 0)))))} -> Gold
A24: CUST1022 | B24: paul fox | C24: 33 | D24: Female | E24: Michaelton | F24: Hawaii | G24: USA | H24: Silver | I24: =TRIM(PROPER(B24)) -> Paul Fox | J24: {=IF(H24<>"", H24, INDEX($H$2:$H$501, MODE(IF($H$2:$H$501<>"", MATCH($H$2:$H$501, $H$2:$H$501, 0)))))} -> Silver
A25: CUST1023 | B25: Jonathan Steele | C25: 52 | D25: Female | E25: Molinabury | F25: Oregon | G25: USA | H25: Silver | I25: =TRIM(PROPER(B25)) -> Jonathan Steele | J25: {=IF(H25<>"", H25, INDEX($H$2:$H$501, MODE(IF($H$2:$H$501<>"", MATCH($H$2:$H$501, $H$2:$H$501, 0)))))} -> Silver
A26: CUST1024 | B26: Heather Collins | C26: 40 | D26: Male | E26: Rogerschester | F26: Idaho | G26: USA | H26: Platinum | I26: =TRIM(PROPER(B26)) -> Heather Collins | J26: {=IF(H26<>"", H26, INDEX($H$2:$H$501, MODE(IF($H$2:$H$501<>"", MATCH($H$2:$H$501, $H$2:$H$501, 0)))))} -> Platinum
A27: CUST1025 | B27: Diana Taylor | C27: 59 | D27: Female | E27: Vasqueztown | F27: California | G27: USA | H27: Bronze | I27: =TRIM(PROPER(B27)) -> Diana Taylor | J27: {=IF(H27<>"", H27, INDEX($H$2:$H$501, MODE(IF($H$2:$H$501<>"", MATCH($H$2:$H$501, $H$2:$H$501, 0)))))} -> Bronze
A28: CUST1026 | B28: Amber Carlson | C28: 18 | D28: Female | E28: East Michellemouth | F28: Missouri | G28: USA | H28: Gold | I28: =TRIM(PROPER(B28)) -> Amber Carlson | J28: {=IF(H28<>"", H28, INDEX($H$2:$H$501, MODE(IF($H$2:$H$501<>"", MATCH($H$2:$H$501, $H$2:$H$501, 0)))))} -> Gold
A29: CUST1027 | B29: Leslie Johnson | C29: 31 | D29: Male | E29: Mollyshire | F29: Utah | G29: USA | I29: =TRIM(PROPER(B29)) -> Leslie Johnson | J29: {=IF(H29<>"", H29, INDEX($H$2:$H$501, MODE(IF($H$2:$H$501<>"", MATCH($H$2:$H$501, $H$2:$H$501, 0)))))} -> Platinum
A30: CUST1028 | B30: Joshua Ryan | C30: 27 | D30: Female | E30: New David | F30: New Jersey | G30: USA | H30: Platinum | I30: =TRIM(PROPER(B30)) -> Joshua Ryan | J30: {=IF(H30<>"", H30, INDEX($H$2:$H$501, MODE(IF($H$2:$H$501<>"", MATCH($H$2:$H$501, $H$2:$H$501, 0)))))} -> Platinum
A31: CUST1029 | B31: David Arnold | C31: 54 | D31: Female | E31: East Jennifer | F31: California | G31: USA | H31: Silver | I31: =TRIM(PROPER(B31)) -> David Arnold | J31: {=IF(H31<>"", H31, INDEX($H$2:$H$501, MODE(IF($H$2:$H$501<>"", MATCH($H$2:$H$501, $H$2:$H$501, 0)))))} -> Silver
A32: CUST1030 | B32: Jessica Acevedo | C32: 64 | D32: Female | E32: Amybury | F32: Pennsylvania | G32: USA | H32: Bronze | I32: =TRIM(PROPER(B32)) -> Jessica Acevedo | J32: {=IF(H32<>"", H32, INDEX($H$2:$H$501, MODE(IF($H$2:$H$501<>"", MATCH($H$2:$H$501, $H$2:$H$501, 0)))))} -> Bronze
A33: CUST1031 | B33: Sarah Vance | C33: 41 | D33: Male | E33: Johnsonville | F33: Oregon | G33: USA | H33: Silver | I33: =TRIM(PROPER(B33)) -> Sarah Vance | J33: {=IF(H33<>"", H33, INDEX($H$2:$H$501, MODE(IF($H$2:$H$501<>"", MATCH($H$2:$H$501, $H$2:$H$501, 0)))))} -> Silver
A34: CUST1032 | B34: Mike Jennings | C34: 48 | D34: Female | E34: Fostermouth | F34: Arizona | G34: USA | H34: Gold | I34: =TRIM(PROPER(B34)) -> Mike Jennings | J34: {=IF(H34<>"", H34, INDEX($H$2:$H$501, MODE(IF($H$2:$H$501<>"", MATCH($H$2:$H$501, $H$2:$H$501, 0)))))} -> Gold
A35: CUST1033 | B35: Robert Jones DDS | C35: 25 | D35: Male | E35: Tristanton | F35: Oklahoma | G35: USA | H35: Platinum | I35: =TRIM(PROPER(B35)) -> Robert Jones Dds | J35: {=IF(H35<>"", H35, INDEX($H$2:$H$501, MODE(IF($H$2:$H$501<>"", MATCH($H$2:$H$501, $H$2:$H$501, 0)))))} -> Platinum
A36: CUST1034 | B36: Christopher Olson | C36: 27 | D36: Female | E36: West Richard | F36: Maryland | G36: USA | H36: Platinum | I36: =TRIM(PROPER(B36)) -> Christopher Olson | J36: {=IF(H36<>"", H36, INDEX($H$2:$H$501, MODE(IF($H$2:$H$501<>"", MATCH($H$2:$H$501, $H$2:$H$501, 0)))))} -> Platinum
A37: CUST1035 | B37: Rachel Myers | C37: 52 | D37: Male | E37: Robertberg | F37: North Dakota | G37: USA | H37: Silver | I37: =TRIM(PROPER(B37)) -> Rachel Myers | J37: {=IF(H37<>"", H37, INDEX($H$2:$H$501, MODE(IF($H$2:$H$501<>"", MATCH($H$2:$H$501, $H$2:$H$501, 0)))))} -> Silver
A38: CUST1036 | B38: Thomas Phillips | C38: 20 | D38: Female | E38: Luisfurt | F38: Georgia | G38: USA | H38: Gold | I38: =TRIM(PROPER(B38)) -> Thomas Phillips | J38: {=IF(H38<>"", H38, INDEX($H$2:$H$501, MODE(IF($H$2:$H$501<>"", MATCH($H$2:$H$501, $H$2:$H$501, 0)))))} -> Gold
A39: CUST1037 | B39: Christopher Carter | C39: 27 | D39: Female | E39: Brendastad | F39: South Dakota | G39: USA | I39: =TRIM(PROPER(B39)) -> Christopher Carter | J39: {=IF(H39<>"", H39, INDEX($H$2:$H$501, MODE(IF($H$2:$H$501<>"", MATCH($H$2:$H$501, $H$2:$H$501, 0)))))} -> Platinum
A40: CUST1038 | B40: Deanna Simpson | C40: 35 | D40: Female | E40: Brownport | F40: North Dakota | G40: USA | H40: Bronze | I40: =TRIM(PROPER(B40)) -> Deanna Simpson | J40: {=IF(H40<>"", H40, INDEX($H$2:$H$501, MODE(IF($H$2:$H$501<>"", MATCH($H$2:$H$501, $H$2:$H$501, 0)))))} -> Bronze
...

Sheet Product
A1: Product id | B1: Product_Name | C1: Category | D1: Sub_Category | E1: Brand | F1: Cost | G1: Stock | H1: Cost Corrected | I1: Stock Corrected
A2: PROD0 | B2: Brother Laser Printer | C2: Electronics | D2: Computer | E2: Hunt Inc | F2: 112.42 | G2: 416 | H2: =IF(F2="", AVERAGEIF($C$2:$C$101, C2, $F$2:$F$101), F2) -> 112.42 | I2: =IF(G2="", AVERAGEIF($C$2:$C$101, C2, $G$2:$G$101), G2) -> 416
A3: PROD1 | B3: Men's Graphic T-Shirt | C3: Clothing | D3: Tops | E3: Terry-Moore | F3: 342.56 | G3: 181 | H3: =IF(F3="", AVERAGEIF($C$2:$C$101, C3, $F$2:$F$101), F3) -> 342.56 | I3: =IF(G3="", AVERAGEIF($C$2:$C$101, C3, $G$2:$G$101), G3) -> 181
A4: PROD2 | B4: Women's Casual Hoodie | C4: Clothing | D4: Outerwear | E4: Sims Inc | G4: 352 | H4: =IF(F4="", AVERAGEIF($C$2:$C$101, C4, $F$2:$F$101), F4) -> 265.73267 | I4: =IF(G4="", AVERAGEIF($C$2:$C$101, C4, $G$2:$G$101), G4) -> 352 | K4: Summary
A5: PROD3 | B5: Men's Running Jacket | C5: Clothing | D5: Outerwear | E5: Pineda Ltd | F5: 364.67 | G5: 452 | H5: =IF(F5="", AVERAGEIF($C$2:$C$101, C5, $F$2:$F$101), F5) -> 364.67 | I5: =IF(G5="", AVERAGEIF($C$2:$C$101, C5, $G$2:$G$101), G5) -> 452 | K5: 1)Cost and Stock finded by if formula
A6: PROD4 | B6: Women's Yoga Pants | C6: Clothing | D6: Bottoms | E6: Gonzales-Davis | F6: 306.46 | G6: 487 | H6: =IF(F6="", AVERAGEIF($C$2:$C$101, C6, $F$2:$F$101), F6) -> 306.46 | I6: =IF(G6="", AVERAGEIF($C$2:$C$101, C6, $G$2:$G$101), G6) -> 487 | K6: 2)P3,P16 change to PROD3, PROD16 by find and replace
A7: PROD5 | B7: Men's Leather Belt | C7: Clothing | D7: Accessories | E7: Baldwin, Garza and Gonzalez | F7: 261 | G7: 59 | H7: =IF(F7="", AVERAGEIF($C$2:$C$101, C7, $F$2:$F$101), F7) -> 261 | I7: =IF(G7="", AVERAGEIF($C$2:$C$101, C7, $G$2:$G$101), G7) -> 59
A8: PROD6 | B8: Herbal Face Moisturizer | C8: Beauty | D8: Skincare | E8: Davidson PLC | F8: 312.8 | G8: 350 | H8: =IF(F8="", AVERAGEIF($C$2:$C$101, C8, $F$2:$F$101), F8) -> 312.8 | I8: =IF(G8="", AVERAGEIF($C$2:$C$101, C8, $G$2:$G$101), G8) -> 350
A9: PROD7 | B9: LED Table Lamp | C9: Home | D9: Lighting | E9: Harrell LLC | F9: 218.86 | G9: 170 | H9: =IF(F9="", AVERAGEIF($C$2:$C$101, C9, $F$2:$F$101), F9) -> 218.86 | I9: =IF(G9="", AVERAGEIF($C$2:$C$101, C9, $G$2:$G$101), G9) -> 170
A10: PROD8 | B10: Wireless Bluetooth Earbuds | C10: Electronics | D10: Audio | E10: Perez-Johnston | F10: 439.07 | G10: 142 | H10: =IF(F10="", AVERAGEIF($C$2:$C$101, C10, $F$2:$F$101), F10) -> 439.07 | I10: =IF(G10="", AVERAGEIF($C$2:$C$101, C10, $G$2:$G$101), G10) -> 142
A11: PROD9 | B11: Adjustable Dumbbell Set | C11: Sports | D11: Fitness | E11: Hill PLC | F11: 495.72 | G11: 323 | H11: =IF(F11="", AVERAGEIF($C$2:$C$101, C11, $F$2:$F$101), F11) -> 495.72 | I11: =IF(G11="", AVERAGEIF($C$2:$C$101, C11, $G$2:$G$101), G11) -> 323
A12: PROD10 | B12: Ceramic Kitchen Bowl Set | C12: Home | D12: Kitchen | E12: Hamilton Group | F12: 298.86 | G12: 308 | H12: =IF(F12="", AVERAGEIF($C$2:$C$101, C12, $F$2:$F$101), F12) -> 298.86 | I12: =IF(G12="", AVERAGEIF($C$2:$C$101, C12, $G$2:$G$101), G12) -> 308
A13: PROD11 | B13: HD Smart TV Stick | C13: Electronics | D13: Accessories | E13: Gibson, Hobbs and Weaver | F13: 449.4 | H13: =IF(F13="", AVERAGEIF($C$2:$C$101, C13, $F$2:$F$101), F13) -> 449.4 | I13: =IF(G13="", AVERAGEIF($C$2:$C$101, C13, $G$2:$G$101), G13) -> 274.7
A14: PROD12 | B14: Hair Strengthening Shampoo | C14: Beauty | D14: Haircare | E14: Rice LLC | F14: 115.82 | G14: 460 | H14: =IF(F14="", AVERAGEIF($C$2:$C$101, C14, $F$2:$F$101), F14) -> 115.82 | I14: =IF(G14="", AVERAGEIF($C$2:$C$101, C14, $G$2:$G$101), G14) -> 460
A15: PROD13 | B15: USB-C Fast Charger | C15: Electronics | D15: Accessories | E15: Dawson-Perkins | F15: 242.23 | G15: 453 | H15: =IF(F15="", AVERAGEIF($C$2:$C$101, C15, $F$2:$F$101), F15) -> 242.23 | I15: =IF(G15="", AVERAGEIF($C$2:$C$101, C15, $G$2:$G$101), G15) -> 453
A16: PROD14 | B16: Decorative Wall Mirror | C16: Home | D16: Decor | E16: Luna, Anderson and Bowman | F16: 48.01 | G16: 439 | H16: =IF(F16="", AVERAGEIF($C$2:$C$101, C16, $F$2:$F$101), F16) -> 48.01 | I16: =IF(G16="", AVERAGEIF($C$2:$C$101, C16, $G$2:$G$101), G16) -> 439
A17: PROD15 | B17: 4K Home Projector | C17: Electronics | D17: Appliances | E17: Thomas LLC | F17: 465.34 | G17: 301 | H17: =IF(F17="", AVERAGEIF($C$2:$C$101, C17, $F$2:$F$101), F17) -> 465.34 | I17: =IF(G17="", AVERAGEIF($C$2:$C$101, C17, $G$2:$G$101), G17) -> 301
A18: PROD16 | B18: Beard Grooming Kit | C18: Beauty | D18: Grooming | E18: Erickson-Green | F18: 337.42 | G18: 256 | H18: =IF(F18="", AVERAGEIF($C$2:$C$101, C18, $F$2:$F$101), F18) -> 337.42 | I18: =IF(G18="", AVERAGEIF($C$2:$C$101, C18, $G$2:$G$101), G18) -> 256
A19: PROD17 | B19: Soccer Training Cone Set | C19: Sports | D19: Accessories | E19: Ford, Murphy and Wilson | F19: 144.53 | G19: 367 | H19: =IF(F19="", AVERAGEIF($C$2:$C$101, C19, $F$2:$F$101), F19) -> 144.53 | I19: =IF(G19="", AVERAGEIF($C$2:$C$101, C19, $G$2:$G$101), G19) -> 367
A20: PROD18 | B20: Women's Denim Jeans | C20: Clothing | D20: Bottoms | E20: Guerra-Hendrix | G20: 343 | H20: =IF(F20="", AVERAGEIF($C$2:$C$101, C20, $F$2:$F$101), F20) -> 265.73267 | I20: =IF(G20="", AVERAGEIF($C$2:$C$101, C20, $G$2:$G$101), G20) -> 343
A21: PROD19 | B21: Knee Support Brace | C21: Sports | D21: Equipment | E21: May-Reese | F21: 21.34 | G21: 65 | H21: =IF(F21="", AVERAGEIF($C$2:$C$101, C21, $F$2:$F$101), F21) -> 21.34 | I21: =IF(G21="", AVERAGEIF($C$2:$C$101, C21, $G$2:$G$101), G21) -> 65
A22: PROD20 | B22: Outdoor Sports Water Bottle | C22: Sports | D22: Accessories | E22: Soto-Ellis | F22: 131.51 | H22: =IF(F22="", AVERAGEIF($C$2:$C$101, C22, $F$2:$F$101), F22) -> 131.51 | I22: =IF(G22="", AVERAGEIF($C$2:$C$101, C22, $G$2:$G$101), G22) -> 281.95833
A23: PROD21 | B23: Multi-Purpose Storage Box | C23: Home | D23: Storage | E23: Gardner-Montes | F23: 123.46 | G23: 76 | H23: =IF(F23="", AVERAGEIF($C$2:$C$101, C23, $F$2:$F$101), F23) -> 123.46 | I23: =IF(G23="", AVERAGEIF($C$2:$C$101, C23, $G$2:$G$101), G23) -> 76
A24: PROD22 | B24: Carbon Fiber Tennis Racket | C24: Sports | D24: Equipment | E24: Flores, Pineda and Rodriguez | F24: 484.62 | G24: 432 | H24: =IF(F24="", AVERAGEIF($C$2:$C$101, C24, $F$2:$F$101), F24) -> 484.62 | I24: =IF(G24="", AVERAGEIF($C$2:$C$101, C24, $G$2:$G$101), G24) -> 432
A25: PROD23 | B25: Men's Formal Shirt | C25: Clothing | D25: Tops | E25: Moon, Mora and Santos | G25: 360 | H25: =IF(F25="", AVERAGEIF($C$2:$C$101, C25, $F$2:$F$101), F25) -> 265.73267 | I25: =IF(G25="", AVERAGEIF($C$2:$C$101, C25, $G$2:$G$101), G25) -> 360
A26: PROD24 | B26: Foldable Camping Chair | C26: Sports | D26: Outdoor | E26: Cook Ltd | F26: 166.06 | G26: 340 | H26: =IF(F26="", AVERAGEIF($C$2:$C$101, C26, $F$2:$F$101), F26) -> 166.06 | I26: =IF(G26="", AVERAGEIF($C$2:$C$101, C26, $G$2:$G$101), G26) -> 340
A27: PROD25 | B27: Women's Scarf Set | C27: Clothing | D27: Accessories | E27: Brown and Sons | F27: 174.02 | G27: 268 | H27: =IF(F27="", AVERAGEIF($C$2:$C$101, C27, $F$2:$F$101), F27) -> 174.02 | I27: =IF(G27="", AVERAGEIF($C$2:$C$101, C27, $G$2:$G$101), G27) -> 268
A28: PROD26 | B28: Wireless Bluetooth Speaker | C28: Electronics | D28: Audio | E28: Reed-Schmidt | F28: 322.41 | G28: 213 | H28: =IF(F28="", AVERAGEIF($C$2:$C$101, C28, $F$2:$F$101), F28) -> 322.41 | I28: =IF(G28="", AVERAGEIF($C$2:$C$101, C28, $G$2:$G$101), G28) -> 213
A29: PROD27 | B29: Decorative Floor Vase | C29: Home | D29: Decor | E29: Khan, Jones and Paul | G29: 378 | H29: =IF(F29="", AVERAGEIF($C$2:$C$101, C29, $F$2:$F$101), F29) -> 234.806 | I29: =IF(G29="", AVERAGEIF($C$2:$C$101, C29, $G$2:$G$101), G29) -> 378
A30: PROD28 | B30: Sports Stopwatch Timer | C30: Sports | D30: Accessories | E30: Burns-Hansen | F30: 38.76 | G30: 137 | H30: =IF(F30="", AVERAGEIF($C$2:$C$101, C30, $F$2:$F$101), F30) -> 38.76 | I30: =IF(G30="", AVERAGEIF($C$2:$C$101, C30, $G$2:$G$101), G30) -> 137
A31: PROD29 | B31: Fabric Sofa Throw Blanket | C31: Home | D31: Decor | E31: Hoffman Group | F31: 218.48 | G31: 276 | H31: =IF(F31="", AVERAGEIF($C$2:$C$101, C31, $F$2:$F$101), F31) -> 218.48 | I31: =IF(G31="", AVERAGEIF($C$2:$C$101, C31, $G$2:$G$101), G31) -> 276
A32: PROD30 | B32: Stainless Steel Cutlery Set | C32: Home | D32: Kitchen | E32: Stevens, Fernandez and Martin | F32: 19.52 | G32: 57 | H32: =IF(F32="", AVERAGEIF($C$2:$C$101, C32, $F$2:$F$101), F32) -> 19.52 | I32: =IF(G32="", AVERAGEIF($C$2:$C$101, C32, $G$2:$G$101), G32) -> 57
A33: PROD31 | B33: Basketball | C33: Sports | D33: Team Sports | E33: Nolan-Snow | F33: 204.39 | G33: 281 | H33: =IF(F33="", AVERAGEIF($C$2:$C$101, C33, $F$2:$F$101), F33) -> 204.39 | I33: =IF(G33="", AVERAGEIF($C$2:$C$101, C33, $G$2:$G$101), G33) -> 281
A34: PROD32 | B34: Vitamin C Face Serum | C34: Beauty | D34: Skincare | E34: Griffin Ltd | F34: 283.83 | G34: 244 | H34: =IF(F34="", AVERAGEIF($C$2:$C$101, C34, $F$2:$F$101), F34) -> 283.83 | I34: =IF(G34="", AVERAGEIF($C$2:$C$101, C34, $G$2:$G$101), G34) -> 244
A35: PROD33 | B35: Modern Wall Clock | C35: Home | D35: Decor | E35: Weiss-Watson | F35: 179.77 | G35: 305 | H35: =IF(F35="", AVERAGEIF($C$2:$C$101, C35, $F$2:$F$101), F35) -> 179.77 | I35: =IF(G35="", AVERAGEIF($C$2:$C$101, C35, $G$2:$G$101), G35) -> 305
A36: PROD34 | B36: Gaming Mechanical Keyboard | C36: Electronics | D36: Computer | E36: Lucero LLC | F36: 419.28 | G36: 86 | H36: =IF(F36="", AVERAGEIF($C$2:$C$101, C36, $F$2:$F$101), F36) -> 419.28 | I36: =IF(G36="", AVERAGEIF($C$2:$C$101, C36, $G$2:$G$101), G36) -> 86
A37: PROD35 | B37: Bedroom Table Lamp | C37: Home | D37: Lighting | E37: Jones LLC | F37: 382.22 | G37: 329 | H37: =IF(F37="", AVERAGEIF($C$2:$C$101, C37, $F$2:$F$101), F37) -> 382.22 | I37: =IF(G37="", AVERAGEIF($C$2:$C$101, C37, $G$2:$G$101), G37) -> 329
A38: PROD36 | B38: Women's Summer Dress | C38: Clothing | D38: Tops | E38: Smith-Mills | F38: 223.43 | G38: 154 | H38: =IF(F38="", AVERAGEIF($C$2:$C$101, C38, $F$2:$F$101), F38) -> 223.43 | I38: =IF(G38="", AVERAGEIF($C$2:$C$101, C38, $G$2:$G$101), G38) -> 154
A39: PROD37 | B39: Men's Casual Sneakers | C39: Clothing | D39: Footwear | E39: Hogan-Lee | F39: 353.47 | G39: 214 | H39: =IF(F39="", AVERAGEIF($C$2:$C$101, C39, $F$2:$F$101), F39) -> 353.47 | I39: =IF(G39="", AVERAGEIF($C$2:$C$101, C39, $G$2:$G$101), G39) -> 214
A40: PROD38 | B40: Sports Water Hydration Pack | C40: Sports | D40: Outdoor | E40: Sims-Smith | F40: 135.61 | G40: 394 | H40: =IF(F40="", AVERAGEIF($C$2:$C$101, C40, $F$2:$F$101), F40) -> 135.61 | I40: =IF(G40="", AVERAGEIF($C$2:$C$101, C40, $G$2:$G$101), G40) -> 394
...

Sheet Sales
A1: Sales_ID | B1: Order_Date | C1: Customer_ID | D1: Product_ID | E1: hj | F1: Store_ID | G1: Quantity | H1: Unit_Price | I1: Discount | J1: Payment_Type | K1: Total_Amount | L1: Quantity Corrected | M1: Unit Price Corrected | N1: Discount Corrected | O1: Total Amount Corrected
A2: SALE0 | B2: 45480 | C2: CUST1409 | D2: PROD97 | E2: =VLOOKUP(D2,Product!$A$2:$I$101,3,FALSE) -> Sports | F2: STORE3 | G2: 1 | H2: 218.04 | I2: 0.09 | J2: Credit Card | K2: 198.4164 | L2: =IF(G2="", AVERAGEIF($E$2:$E$101, E3, $G$2:$G$101), G2) -> 1 | M2: =IF(H2="", IFERROR(AVERAGEIF($E$2:$E$101, E2, $H$2:$H$101), ""), H2) -> 218.04 | N2: =IF(I2="", AVERAGEIF($E$2:$E$101, E3, $I$2:$I$101), I2) -> 0.09 | O2: =IF(K2="", AVERAGEIF($E$2:$E$101, E3, $K$2:$K$101), K2) -> 198.4164
A3: SALE1 | B3: 45285 | C3: CUST1467 | D3: PROD74 | E3: =VLOOKUP(D3,Product!$A$2:$I$101,3,FALSE) -> Electronics | F3: STORE17 | G3: 3 | H3: 104.47 | I3: 0.27 | J3: PayPal | K3: 228.7893 | L3: =IF(G3="", AVERAGEIF($E$2:$E$101, E4, $G$2:$G$101), G3) -> 3 | M3: =IF(H3="", IFERROR(AVERAGEIF($E$2:$E$101, E3, $H$2:$H$101), ""), H3) -> 104.47 | N3: =IF(I3="", AVERAGEIF($E$2:$E$101, E4, $I$2:$I$101), I3) -> 0.27 | O3: =IF(K3="", AVERAGEIF($E$2:$E$101, E4, $K$2:$K$101), K3) -> 228.7893 | Q3: Summary
A4: SALE2 | B4: 45446 | C4: CUST1056 | D4: PROD49 | E4: =VLOOKUP(D4,Product!$A$2:$I$101,3,FALSE) -> Beauty | F4: STORE8 | G4: 4 | H4: 914.05 | I4: 0.25 | J4: Credit Card | K4: 2742.15 | L4: =IF(G4="", AVERAGEIF($E$2:$E$101, E5, $G$2:$G$101), G4) -> 4 | M4: =IF(H4="", IFERROR(AVERAGEIF($E$2:$E$101, E4, $H$2:$H$101), ""), H4) -> 914.05 | N4: =IF(I4="", AVERAGEIF($E$2:$E$101, E5, $I$2:$I$101), I4) -> 0.25 | O4: =IF(K4="", AVERAGEIF($E$2:$E$101, E5, $K$2:$K$101), K4) -> 2742.15 | Q4: 1)use if, iferror, averageif to find quantity, unit price,
A5: SALE3 | B5: 45259 | C5: CUST1346 | D5: PROD76 | E5: =VLOOKUP(D5,Product!$A$2:$I$101,3,FALSE) -> Electronics | F5: STORE8 | G5: 1 | H5: 921.51 | I5: 0.16 | J5: COD | K5: 774.0684 | L5: =IF(G5="", AVERAGEIF($E$2:$E$101, E6, $G$2:$G$101), G5) -> 1 | M5: =IF(H5="", IFERROR(AVERAGEIF($E$2:$E$101, E5, $H$2:$H$101), ""), H5) -> 921.51 | N5: =IF(I5="", AVERAGEIF($E$2:$E$101, E6, $I$2:$I$101), I5) -> 0.16 | O5: =IF(K5="", AVERAGEIF($E$2:$E$101, E6, $K$2:$K$101), K5) -> 774.0684 | Q5: discount, total amount of missing values
A6: SALE4 | B6: 45297 | C6: CUST1493 | D6: PROD59 | E6: =VLOOKUP(D6,Product!$A$2:$I$101,3,FALSE) -> Beauty | F6: STORE5 | G6: 3 | H6: 745.3 | I6: 0.18 | J6: Credit Card | K6: 1833.438 | L6: =IF(G6="", AVERAGEIF($E$2:$E$101, E7, $G$2:$G$101), G6) -> 3 | M6: =IF(H6="", IFERROR(AVERAGEIF($E$2:$E$101, E6, $H$2:$H$101), ""), H6) -> 745.3 | N6: =IF(I6="", AVERAGEIF($E$2:$E$101, E7, $I$2:$I$101), I6) -> 0.18 | O6: =IF(K6="", AVERAGEIF($E$2:$E$101, E7, $K$2:$K$101), K6) -> 1833.438 | Q6: 2) used text formula to makes rupees in unit price
A7: SALE5 | B7: 45499 | C7: CUST1116 | D7: PROD15 | E7: =VLOOKUP(D7,Product!$A$2:$I$101,3,FALSE) -> Electronics | F7: STORE7 | G7: 3 | H7: 147.01 | I7: 0.19 | J7: COD | K7: 357.2343 | L7: =IF(G7="", AVERAGEIF($E$2:$E$101, E8, $G$2:$G$101), G7) -> 3 | M7: =IF(H7="", IFERROR(AVERAGEIF($E$2:$E$101, E7, $H$2:$H$101), ""), H7) -> 147.01 | N7: =IF(I7="", AVERAGEIF($E$2:$E$101, E8, $I$2:$I$101), I7) -> 0.19 | O7: =IF(K7="", AVERAGEIF($E$2:$E$101, E8, $K$2:$K$101), K7) -> 357.2343
A8: SALE6 | B8: 45850 | C8: CUST1016 | D8: PROD56 | E8: =VLOOKUP(D8,Product!$A$2:$I$101,3,FALSE) -> Home | F8: STORE4 | G8: 2 | H8: 785.31 | I8: 0.15 | J8: PayPal | K8: 1335.027 | L8: =IF(G8="", AVERAGEIF($E$2:$E$101, E9, $G$2:$G$101), G8) -> 2 | M8: =IF(H8="", IFERROR(AVERAGEIF($E$2:$E$101, E8, $H$2:$H$101), ""), H8) -> 785.31 | N8: =IF(I8="", AVERAGEIF($E$2:$E$101, E9, $I$2:$I$101), I8) -> 0.15 | O8: =IF(K8="", AVERAGEIF($E$2:$E$101, E9, $K$2:$K$101), K8) -> 1335.027
A9: SALE7 | B9: 45248 | C9: CUST1152 | D9: PROD70 | E9: =VLOOKUP(D9,Product!$A$2:$I$101,3,FALSE) -> Home | F9: STORE8 | G9: 4 | H9: 342.39 | I9: 0.23 | J9: PayPal | K9: 1054.5612 | L9: =IF(G9="", AVERAGEIF($E$2:$E$101, E10, $G$2:$G$101), G9) -> 4 | M9: =IF(H9="", IFERROR(AVERAGEIF($E$2:$E$101, E9, $H$2:$H$101), ""), H9) -> 342.39 | N9: =IF(I9="", AVERAGEIF($E$2:$E$101, E10, $I$2:$I$101), I9) -> 0.23 | O9: =IF(K9="", AVERAGEIF($E$2:$E$101, E10, $K$2:$K$101), K9) -> 1054.5612
A10: SALE8 | B10: 45781 | C10: CUST1187 | D10: PROD99 | E10: =VLOOKUP(D10,Product!$A$2:$I$101,3,FALSE) -> Home | F10: STORE5 | H10: 448.25 | I10: 0.07 | J10: PayPal | K10: 1250.6175 | L10: =IF(G10="", AVERAGEIF($E$2:$E$101, E11, $G$2:$G$101), G10) -> 2.1875 | M10: =IF(H10="", IFERROR(AVERAGEIF($E$2:$E$101, E10, $H$2:$H$101), ""), H10) -> 448.25 | N10: =IF(I10="", AVERAGEIF($E$2:$E$101, E11, $I$2:$I$101), I10) -> 0.07 | O10: =IF(K10="", AVERAGEIF($E$2:$E$101, E11, $K$2:$K$101), K10) -> 1250.6175
A11: SALE9 | B11: 45869 | C11: CUST1464 | D11: PROD33 | E11: =VLOOKUP(D11,Product!$A$2:$I$101,3,FALSE) -> Home | F11: STORE0 | G11: 2 | H11: 873.17 | I11: 0.23 | J11: PayPal | K11: 1344.6818 | L11: =IF(G11="", AVERAGEIF($E$2:$E$101, E12, $G$2:$G$101), G11) -> 2 | M11: =IF(H11="", IFERROR(AVERAGEIF($E$2:$E$101, E11, $H$2:$H$101), ""), H11) -> 873.17 | N11: =IF(I11="", AVERAGEIF($E$2:$E$101, E12, $I$2:$I$101), I11) -> 0.23 | O11: =IF(K11="", AVERAGEIF($E$2:$E$101, E12, $K$2:$K$101), K11) -> 1344.6818
A12: SALE10 | B12: 45335 | C12: CUST1065 | D12: PROD24 | E12: =VLOOKUP(D12,Product!$A$2:$I$101,3,FALSE) -> Sports | F12: STORE14 | G12: 1 | H12: 278.63 | I12: 0.07 | J12: Credit Card | K12: 259.1259 | L12: =IF(G12="", AVERAGEIF($E$2:$E$101, E13, $G$2:$G$101), G12) -> 1 | M12: =IF(H12="", IFERROR(AVERAGEIF($E$2:$E$101, E12, $H$2:$H$101), ""), H12) -> 278.63 | N12: =IF(I12="", AVERAGEIF($E$2:$E$101, E13, $I$2:$I$101), I12) -> 0.07 | O12: =IF(K12="", AVERAGEIF($E$2:$E$101, E13, $K$2:$K$101), K12) -> 259.1259
A13: SALE11 | B13: 45801 | C13: CUST1320 | D13: PROD39 | E13: =VLOOKUP(D13,Product!$A$2:$I$101,3,FALSE) -> Electronics | F13: STORE1 | G13: 4 | H13: 286.92 | I13: 0.17 | J13: Credit Card | K13: 952.5744 | L13: =IF(G13="", AVERAGEIF($E$2:$E$101, E14, $G$2:$G$101), G13) -> 4 | M13: =IF(H13="", IFERROR(AVERAGEIF($E$2:$E$101, E13, $H$2:$H$101), ""), H13) -> 286.92 | N13: =IF(I13="", AVERAGEIF($E$2:$E$101, E14, $I$2:$I$101), I13) -> 0.17 | O13: =IF(K13="", AVERAGEIF($E$2:$E$101, E14, $K$2:$K$101), K13) -> 952.5744
A14: SALE12 | B14: 45528 | C14: CUST1237 | D14: PROD88 | E14: =VLOOKUP(D14,Product!$A$2:$I$101,3,FALSE) -> Sports | F14: STORE4 | G14: 4 | H14: 644.58 | I14: 0.01 | J14: Credit Card | K14: 2552.5368 | L14: =IF(G14="", AVERAGEIF($E$2:$E$101, E15, $G$2:$G$101), G14) -> 4 | M14: =IF(H14="", IFERROR(AVERAGEIF($E$2:$E$101, E14, $H$2:$H$101), ""), H14) -> 644.58 | N14: =IF(I14="", AVERAGEIF($E$2:$E$101, E15, $I$2:$I$101), I14) -> 0.01 | O14: =IF(K14="", AVERAGEIF($E$2:$E$101, E15, $K$2:$K$101), K14) -> 2552.5368
A15: SALE13 | B15: 45875 | C15: CUST1443 | D15: PROD34 | E15: =VLOOKUP(D15,Product!$A$2:$I$101,3,FALSE) -> Electronics | F15: STORE16 | G15: 2 | H15: 316.9 | I15: 0.3 | J15: PayPal | K15: 443.66 | L15: =IF(G15="", AVERAGEIF($E$2:$E$101, E16, $G$2:$G$101), G15) -> 2 | M15: =IF(H15="", IFERROR(AVERAGEIF($E$2:$E$101, E15, $H$2:$H$101), ""), H15) -> 316.9 | N15: =IF(I15="", AVERAGEIF($E$2:$E$101, E16, $I$2:$I$101), I15) -> 0.3 | O15: =IF(K15="", AVERAGEIF($E$2:$E$101, E16, $K$2:$K$101), K15) -> 443.66
A16: SALE14 | B16: 45829 | C16: CUST1348 | D16: PROD24 | E16: =VLOOKUP(D16,Product!$A$2:$I$101,3,FALSE) -> Sports | F16: STORE15 | G16: 4 | H16: 403.47 | I16: 0.29 | J16: PayPal | K16: 1145.8548 | L16: =IF(G16="", AVERAGEIF($E$2:$E$101, E17, $G$2:$G$101), G16) -> 4 | M16: =IF(H16="", IFERROR(AVERAGEIF($E$2:$E$101, E16, $H$2:$H$101), ""), H16) -> 403.47 | N16: =IF(I16="", AVERAGEIF($E$2:$E$101, E17, $I$2:$I$101), I16) -> 0.29 | O16: =IF(K16="", AVERAGEIF($E$2:$E$101, E17, $K$2:$K$101), K16) -> 1145.8548
A17: SALE15 | B17: 45636 | C17: CUST1435 | D17: PROD36 | E17: =VLOOKUP(D17,Product!$A$2:$I$101,3,FALSE) -> Clothing | F17: STORE9 | H17: 871.34 | I17: 0.04 | J17: COD | K17: 2509.4592 | L17: =IF(G17="", AVERAGEIF($E$2:$E$101, E18, $G$2:$G$101), G17) -> 2.2962963 | M17: =IF(H17="", IFERROR(AVERAGEIF($E$2:$E$101, E17, $H$2:$H$101), ""), H17) -> 871.34 | N17: =IF(I17="", AVERAGEIF($E$2:$E$101, E18, $I$2:$I$101), I17) -> 0.04 | O17: =IF(K17="", AVERAGEIF($E$2:$E$101, E18, $K$2:$K$101), K17) -> 2509.4592
A18: SALE16 | B18: 45913 | C18: CUST1276 | D18: PROD65 | E18: =VLOOKUP(D18,Product!$A$2:$I$101,3,FALSE) -> Sports | F18: STORE19 | G18: 2 | H18: 451.98 | I18: 0.25 | J18: Credit Card | K18: 677.97 | L18: =IF(G18="", AVERAGEIF($E$2:$E$101, E19, $G$2:$G$101), G18) -> 2 | M18: =IF(H18="", IFERROR(AVERAGEIF($E$2:$E$101, E18, $H$2:$H$101), ""), H18) -> 451.98 | N18: =IF(I18="", AVERAGEIF($E$2:$E$101, E19, $I$2:$I$101), I18) -> 0.25 | O18: =IF(K18="", AVERAGEIF($E$2:$E$101, E19, $K$2:$K$101), K18) -> 677.97
A19: SALE17 | B19: 45637 | C19: CUST1079 | D19: PROD27 | E19: =VLOOKUP(D19,Product!$A$2:$I$101,3,FALSE) -> Home | F19: STORE4 | G19: 2 | H19: 502.69 | I19: 0.23 | J19: Credit Card | K19: 774.1426 | L19: =IF(G19="", AVERAGEIF($E$2:$E$101, E20, $G$2:$G$101), G19) -> 2 | M19: =IF(H19="", IFERROR(AVERAGEIF($E$2:$E$101, E19, $H$2:$H$101), ""), H19) -> 502.69 | N19: =IF(I19="", AVERAGEIF($E$2:$E$101, E20, $I$2:$I$101), I19) -> 0.23 | O19: =IF(K19="", AVERAGEIF($E$2:$E$101, E20, $K$2:$K$101), K19) -> 774.1426
A20: SALE18 | B20: 45517 | C20: CUST1094 | D20: PROD39 | E20: =VLOOKUP(D20,Product!$A$2:$I$101,3,FALSE) -> Electronics | F20: STORE4 | G20: 2 | H20: 559.23 | I20: 0.25 | J20: COD | K20: 838.845 | L20: =IF(G20="", AVERAGEIF($E$2:$E$101, E21, $G$2:$G$101), G20) -> 2 | M20: =IF(H20="", IFERROR(AVERAGEIF($E$2:$E$101, E20, $H$2:$H$101), ""), H20) -> 559.23 | N20: =IF(I20="", AVERAGEIF($E$2:$E$101, E21, $I$2:$I$101), I20) -> 0.25 | O20: =IF(K20="", AVERAGEIF($E$2:$E$101, E21, $K$2:$K$101), K20) -> 838.845
A21: SALE19 | B21: 45369 | C21: CUST1239 | D21: PROD60 | E21: =VLOOKUP(D21,Product!$A$2:$I$101,3,FALSE) -> Beauty | F21: STORE13 | G21: 4 | I21: 0.04 | J21: COD | K21: 1782.4512 | L21: =IF(G21="", AVERAGEIF($E$2:$E$101, E22, $G$2:$G$101), G21) -> 4 | M21: =IF(H21="", AVERAGEIF($E$2:$E$101, E22, $H$2:$H$101), H21) -> 443.50037 | N21: =IF(I21="", AVERAGEIF($E$2:$E$101, E22, $I$2:$I$101), I21) -> 0.04 | O21: =IF(K21="", AVERAGEIF($E$2:$E$101, E22, $K$2:$K$101), K21) -> 1782.4512
A22: SALE20 | B22: 45843 | C22: CUST1144 | D22: PROD72 | E22: =VLOOKUP(D22,Product!$A$2:$I$101,3,FALSE) -> Sports | F22: STORE17 | G22: 3 | H22: 986.04 | I22: 0.27 | J22: COD | K22: 2159.4276 | L22: =IF(G22="", AVERAGEIF($E$2:$E$101, E23, $G$2:$G$101), G22) -> 3 | M22: =IF(H22="", IFERROR(AVERAGEIF($E$2:$E$101, E22, $H$2:$H$101), ""), H22) -> 986.04 | N22: =IF(I22="", AVERAGEIF($E$2:$E$101, E23, $I$2:$I$101), I22) -> 0.27 | O22: =IF(K22="", AVERAGEIF($E$2:$E$101, E23, $K$2:$K$101), K22) -> 2159.4276
A23: SALE21 | B23: 45447 | C23: CUST1396 | D23: PROD43 | E23: =VLOOKUP(D23,Product!$A$2:$I$101,3,FALSE) -> Electronics | F23: STORE18 | G23: 1 | H23: 589.56 | I23: 0.22 | J23: Credit Card | K23: 459.8568 | L23: =IF(G23="", AVERAGEIF($E$2:$E$101, E24, $G$2:$G$101), G23) -> 1 | M23: =IF(H23="", IFERROR(AVERAGEIF($E$2:$E$101, E23, $H$2:$H$101), ""), H23) -> 589.56 | N23: =IF(I23="", AVERAGEIF($E$2:$E$101, E24, $I$2:$I$101), I23) -> 0.22 | O23: =IF(K23="", AVERAGEIF($E$2:$E$101, E24, $K$2:$K$101), K23) -> 459.8568
A24: SALE22 | B24: 45394 | C24: CUST1476 | D24: PROD69 | E24: =VLOOKUP(D24,Product!$A$2:$I$101,3,FALSE) -> Clothing | F24: STORE10 | G24: 3 | H24: 979.42 | I24: 0.03 | J24: PayPal | K24: 2850.1122 | L24: =IF(G24="", AVERAGEIF($E$2:$E$101, E25, $G$2:$G$101), G24) -> 3 | M24: =IF(H24="", IFERROR(AVERAGEIF($E$2:$E$101, E24, $H$2:$H$101), ""), H24) -> 979.42 | N24: =IF(I24="", AVERAGEIF($E$2:$E$101, E25, $I$2:$I$101), I24) -> 0.03 | O24: =IF(K24="", AVERAGEIF($E$2:$E$101, E25, $K$2:$K$101), K24) -> 2850.1122
A25: SALE23 | B25: 45466 | C25: CUST1368 | D25: PROD12 | E25: =VLOOKUP(D25,Product!$A$2:$I$101,3,FALSE) -> Beauty | F25: STORE8 | G25: 1 | H25: 719.28 | I25: 0.08 | J25: Credit Card | K25: 661.7376 | L25: =IF(G25="", AVERAGEIF($E$2:$E$101, E26, $G$2:$G$101), G25) -> 1 | M25: =IF(H25="", IFERROR(AVERAGEIF($E$2:$E$101, E25, $H$2:$H$101), ""), H25) -> 719.28 | N25: =IF(I25="", AVERAGEIF($E$2:$E$101, E26, $I$2:$I$101), I25) -> 0.08 | O25: =IF(K25="", AVERAGEIF($E$2:$E$101, E26, $K$2:$K$101), K25) -> 661.7376
A26: SALE24 | B26: 45908 | C26: CUST1186 | D26: PROD67 | E26: =VLOOKUP(D26,Product!$A$2:$I$101,3,FALSE) -> Electronics | F26: STORE6 | G26: 3 | H26: 77.6 | I26: 0.07 | J26: Credit Card | K26: 216.504 | L26: =IF(G26="", AVERAGEIF($E$2:$E$101, E27, $G$2:$G$101), G26) -> 3 | M26: =IF(H26="", IFERROR(AVERAGEIF($E$2:$E$101, E26, $H$2:$H$101), ""), H26) -> 77.6 | N26: =IF(I26="", AVERAGEIF($E$2:$E$101, E27, $I$2:$I$101), I26) -> 0.07 | O26: =IF(K26="", AVERAGEIF($E$2:$E$101, E27, $K$2:$K$101), K26) -> 216.504
A27: SALE25 | B27: 45552 | C27: CUST1381 | D27: PROD5 | E27: =VLOOKUP(D27,Product!$A$2:$I$101,3,FALSE) -> Clothing | F27: STORE3 | G27: 4 | H27: 852.71 | I27: 0.14 | J27: PayPal | K27: 2933.3224 | L27: =IF(G27="", AVERAGEIF($E$2:$E$101, E28, $G$2:$G$101), G27) -> 4 | M27: =IF(H27="", IFERROR(AVERAGEIF($E$2:$E$101, E27, $H$2:$H$101), ""), H27) -> 852.71 | N27: =IF(I27="", AVERAGEIF($E$2:$E$101, E28, $I$2:$I$101), I27) -> 0.14 | O27: =IF(K27="", AVERAGEIF($E$2:$E$101, E28, $K$2:$K$101), K27) -> 2933.3224
A28: SALE26 | B28: 45294 | C28: CUST1213 | D28: PROD98 | E28: =VLOOKUP(D28,Product!$A$2:$I$101,3,FALSE) -> Electronics | F28: STORE8 | G28: 4 | H28: 156.16 | J28: Credit Card | K28: 599.6544 | L28: =IF(G28="", AVERAGEIF($E$2:$E$101, E29, $G$2:$G$101), G28) -> 4 | M28: =IF(H28="", IFERROR(AVERAGEIF($E$2:$E$101, E28, $H$2:$H$101), ""), H28) -> 156.16 | N28: =IF(I28="", AVERAGEIF($E$2:$E$101, E29, $I$2:$I$101), I28) -> 0.17894737 | O28: =IF(K28="", AVERAGEIF($E$2:$E$101, E29, $K$2:$K$101), K28) -> 599.6544
A29: SALE27 | B29: 45710 | C29: CUST1200 | D29: PROD77 | E29: =VLOOKUP(D29,Product!$A$2:$I$101,3,FALSE) -> Electronics | F29: STORE8 | G29: 3 | H29: 815.49 | I29: 0.17 | J29: Credit Card | K29: 2030.5701 | L29: =IF(G29="", AVERAGEIF($E$2:$E$101, E30, $G$2:$G$101), G29) -> 3 | M29: =IF(H29="", IFERROR(AVERAGEIF($E$2:$E$101, E29, $H$2:$H$101), ""), H29) -> 815.49 | N29: =IF(I29="", AVERAGEIF($E$2:$E$101, E30, $I$2:$I$101), I29) -> 0.17 | O29: =IF(K29="", AVERAGEIF($E$2:$E$101, E30, $K$2:$K$101), K29) -> 2030.5701
A30: SALE28 | B30: 45923 | C30: CUST1148 | D30: PROD13 | E30: =VLOOKUP(D30,Product!$A$2:$I$101,3,FALSE) -> Electronics | F30: STORE2 | G30: 2 | H30: 74.21 | I30: 0.11 | J30: PayPal | K30: 132.0938 | L30: =IF(G30="", AVERAGEIF($E$2:$E$101, E31, $G$2:$G$101), G30) -> 2 | M30: =IF(H30="", IFERROR(AVERAGEIF($E$2:$E$101, E30, $H$2:$H$101), ""), H30) -> 74.21 | N30: =IF(I30="", AVERAGEIF($E$2:$E$101, E31, $I$2:$I$101), I30) -> 0.11 | O30: =IF(K30="", AVERAGEIF($E$2:$E$101, E31, $K$2:$K$101), K30) -> 132.0938
A31: SALE29 | B31: 45302 | C31: CUST1348 | D31: PROD99 | E31: =VLOOKUP(D31,Product!$A$2:$I$101,3,FALSE) -> Home | F31: STORE3 | H31: 451.67 | I31: 0.15 | J31: Credit Card | K31: 1535.678 | L31: =IF(G31="", AVERAGEIF($E$2:$E$101, E32, $G$2:$G$101), G31) -> 2.6923077 | M31: =IF(H31="", IFERROR(AVERAGEIF($E$2:$E$101, E31, $H$2:$H$101), ""), H31) -> 451.67 | N31: =IF(I31="", AVERAGEIF($E$2:$E$101, E32, $I$2:$I$101), I31) -> 0.15 | O31: =IF(K31="", AVERAGEIF($E$2:$E$101, E32, $K$2:$K$101), K31) -> 1535.678
A32: SALE30 | B32: 45217 | C32: CUST1028 | D32: PROD5 | E32: =VLOOKUP(D32,Product!$A$2:$I$101,3,FALSE) -> Clothing | F32: STORE19 | G32: 1 | H32: 429.38 | I32: 0.13 | J32: PayPal | K32: 373.5606 | L32: =IF(G32="", AVERAGEIF($E$2:$E$101, E33, $G$2:$G$101), G32) -> 1 | M32: =IF(H32="", IFERROR(AVERAGEIF($E$2:$E$101, E32, $H$2:$H$101), ""), H32) -> 429.38 | N32: =IF(I32="", AVERAGEIF($E$2:$E$101, E33, $I$2:$I$101), I32) -> 0.13 | O32: =IF(K32="", AVERAGEIF($E$2:$E$101, E33, $K$2:$K$101), K32) -> 373.5606
A33: SALE31 | B33: 45593 | C33: CUST1412 | D33: PROD53 | E33: =VLOOKUP(D33,Product!$A$2:$I$101,3,FALSE) -> Clothing | F33: STORE12 | G33: 2 | H33: 148.96 | I33: 0.03 | J33: COD | K33: 288.9824 | L33: =IF(G33="", AVERAGEIF($E$2:$E$101, E34, $G$2:$G$101), G33) -> 2 | M33: =IF(H33="", IFERROR(AVERAGEIF($E$2:$E$101, E33, $H$2:$H$101), ""), H33) -> 148.96 | N33: =IF(I33="", AVERAGEIF($E$2:$E$101, E34, $I$2:$I$101), I33) -> 0.03 | O33: =IF(K33="", AVERAGEIF($E$2:$E$101, E34, $K$2:$K$101), K33) -> 288.9824
A34: SALE32 | B34: 45597 | C34: CUST1398 | D34: PROD75 | E34: =VLOOKUP(D34,Product!$A$2:$I$101,3,FALSE) -> Clothing | F34: STORE8 | G34: 4 | H34: 313.83 | I34: 0.08 | J34: Credit Card | K34: 1154.8944 | L34: =IF(G34="", AVERAGEIF($E$2:$E$101, E35, $G$2:$G$101), G34) -> 4 | M34: =IF(H34="", IFERROR(AVERAGEIF($E$2:$E$101, E34, $H$2:$H$101), ""), H34) -> 313.83 | N34: =IF(I34="", AVERAGEIF($E$2:$E$101, E35, $I$2:$I$101), I34) -> 0.08 | O34: =IF(K34="", AVERAGEIF($E$2:$E$101, E35, $K$2:$K$101), K34) -> 1154.8944
A35: SALE33 | B35: 45620 | C35: CUST1453 | D35: PROD12 | E35: =VLOOKUP(D35,Product!$A$2:$I$101,3,FALSE) -> Beauty | F35: STORE6 | G35: 2 | H35: 717.31 | I35: 0.15 | J35: Credit Card | K35: 1219.427 | L35: =IF(G35="", AVERAGEIF($E$2:$E$101, E36, $G$2:$G$101), G35) -> 2 | M35: =IF(H35="", IFERROR(AVERAGEIF($E$2:$E$101, E35, $H$2:$H$101), ""), H35) -> 717.31 | N35: =IF(I35="", AVERAGEIF($E$2:$E$101, E36, $I$2:$I$101), I35) -> 0.15 | O35: =IF(K35="", AVERAGEIF($E$2:$E$101, E36, $K$2:$K$101), K35) -> 1219.427
A36: SALE34 | B36: 45215 | C36: CUST1344 | D36: PROD79 | E36: =VLOOKUP(D36,Product!$A$2:$I$101,3,FALSE) -> Home | F36: STORE1 | H36: 873.22 | I36: 0.18 | J36: Credit Card | K36: 2148.1212 | L36: =IF(G36="", AVERAGEIF($E$2:$E$101, E37, $G$2:$G$101), G36) -> 2.5 | M36: =IF(H36="", IFERROR(AVERAGEIF($E$2:$E$101, E36, $H$2:$H$101), ""), H36) -> 873.22 | N36: =IF(I36="", AVERAGEIF($E$2:$E$101, E37, $I$2:$I$101), I36) -> 0.18 | O36: =IF(K36="", AVERAGEIF($E$2:$E$101, E37, $K$2:$K$101), K36) -> 2148.1212
A37: SALE35 | B37: 45878 | C37: CUST1218 | D37: PROD16 | E37: =VLOOKUP(D37,Product!$A$2:$I$101,3,FALSE) -> Beauty | F37: STORE3 | G37: 4 | H37: 109.36 | I37: 0.19 | J37: COD | K37: 354.3264 | L37: =IF(G37="", AVERAGEIF($E$2:$E$101, E38, $G$2:$G$101), G37) -> 4 | M37: =IF(H37="", IFERROR(AVERAGEIF($E$2:$E$101, E37, $H$2:$H$101), ""), H37) -> 109.36 | N37: =IF(I37="", AVERAGEIF($E$2:$E$101, E38, $I$2:$I$101), I37) -> 0.19 | O37: =IF(K37="", AVERAGEIF($E$2:$E$101, E38, $K$2:$K$101), K37) -> 354.3264
A38: SALE36 | B38: 45635 | C38: CUST1086 | D38: PROD5 | E38: =VLOOKUP(D38,Product!$A$2:$I$101,3,FALSE) -> Clothing | F38: STORE7 | G38: 3 | H38: 559.52 | I38: 0.16 | J38: PayPal | K38: 1409.9904 | L38: =IF(G38="", AVERAGEIF($E$2:$E$101, E39, $G$2:$G$101), G38) -> 3 | M38: =IF(H38="", IFERROR(AVERAGEIF($E$2:$E$101, E38, $H$2:$H$101), ""), H38) -> 559.52 | N38: =IF(I38="", AVERAGEIF($E$2:$E$101, E39, $I$2:$I$101), I38) -> 0.16 | O38: =IF(K38="", AVERAGEIF($E$2:$E$101, E39, $K$2:$K$101), K38) -> 1409.9904
A39: SALE37 | B39: 45329 | C39: CUST1492 | D39: PROD10 | E39: =VLOOKUP(D39,Product!$A$2:$I$101,3,FALSE) -> Home | F39: STORE17 | G39: 3 | H39: 121.76 | I39: 0.27 | J39: PayPal | K39: 266.6544 | L39: =IF(G39="", AVERAGEIF($E$2:$E$101, E40, $G$2:$G$101), G39) -> 3 | M39: =IF(H39="", IFERROR(AVERAGEIF($E$2:$E$101, E39, $H$2:$H$101), ""), H39) -> 121.76 | N39: =IF(I39="", AVERAGEIF($E$2:$E$101, E40, $I$2:$I$101), I39) -> 0.27 | O39: =IF(K39="", AVERAGEIF($E$2:$E$101, E40, $K$2:$K$101), K39) -> 266.6544
A40: SALE38 | B40: 45378 | C40: CUST1189 | D40: PROD33 | E40: =VLOOKUP(D40,Product!$A$2:$I$101,3,FALSE) -> Home | F40: STORE13 | G40: 4 | H40: 735.32 | I40: 0.06 | J40: COD | K40: 2764.8032 | L40: =IF(G40="", AVERAGEIF($E$2:$E$101, E41, $G$2:$G$101), G40) -> 4 | M40: =IF(H40="", IFERROR(AVERAGEIF($E$2:$E$101, E40, $H$2:$H$101), ""), H40) -> 735.32 | N40: =IF(I40="", AVERAGEIF($E$2:$E$101, E41, $I$2:$I$101), I40) -> 0.06 | O40: =IF(K40="", AVERAGEIF($E$2:$E$101, E41, $K$2:$K$101), K40) -> 2764.8032
...

Sheet Summary Statistics
A1: Total Sales | D1: Cost | G1: Stock
A3: Mean | B3: 1087.7408 | D3: Mean | E3: 256.44308 | G3: Mean | H3: 273.42239
A4: Standard Error | B4: 18.359318 | D4: Standard Error | E4: 2.9573834 | G4: Standard Error | H4: 2.8696345
A5: Median | B5: 868.4564 | D5: Median | E5: 250.41615 | G5: Median | H5: 276
A6: Mode | B6: 1078.9595 | D6: Mode | E6: 265.73267 | G6: Mode | H6: 301
A7: Standard Deviation | B7: 819.61557 | D7: Standard Deviation | E7: 132.22514 | G7: Standard Deviation | H7: 128.30187
A8: Sample Variance | B8: 671769.68 | D8: Sample Variance | E8: 17483.487 | G8: Sample Variance | H8: 16461.37
A9: Kurtosis | B9: 0.048453215 | D9: Kurtosis | E9: -1.0231998 | G9: Kurtosis | H9: -1.1349752
A10: Skewness | B10: 0.88049627 | D10: Skewness | E10: 0.017982216 | G10: Skewness | H10: -0.0128037
A11: Range | B11: 3889.7838 | D11: Range | E11: 478.41 | G11: Range | H11: 439
A12: Minimum | B12: 18.459 | D12: Minimum | E12: 17.31 | G12: Minimum | H12: 57
A13: Maximum | B13: 3908.2428 | D13: Maximum | E13: 495.72 | G13: Maximum | H13: 496
A14: Sum | B14: 2167867.5 | D14: Sum | E14: 512629.72 | G14: Sum | H14: 546571.37
A15: Count | B15: 1993 | D15: Count | E15: 1999 | G15: Count | H15: 1999
A18: Summary
A19: 1) I find summary statistics using analysis toolpak

Sheet Cleaned Table
A1: Customer_ID | B1: Name | C1: Age | D1: Gender | E1: City | F1: State | G1: Country | H1: Loyalty_Level | I1: Product_ID | J1: Product_Name | K1: Category | L1: Sub_Category | M1: Brand | N1: Cost | O1: Stock | P1: Store_ID | Q1: Store_Name | R1: Region | S1: City2 | T1: Store_Type | U1: Sales_ID | V1: Order_Date | W1: Quantity | X1: Unit_Price | Y1: Discount | Z1: Payment_Type | AA1: Total_Amount
